<mujoco>
  <option timestep="0.001" />
  <compiler angle="radian" autolimits="true" meshdir="../meshes" />
  <default>
    <joint limited="true" armature="0.05" damping="0.01"/>
    <motor ctrllimited="true" ctrlrange="-100 100"/>
    <equality solref="0.005 1"/>
  </default>
  <asset>
    <mesh name="pelvis" file="pelvis.STL" />
    <mesh name="pelvis_contour_link" file="pelvis_contour_link.STL" />
    <mesh name="left_hip_pitch_link" file="left_hip_pitch_link.STL" />
    <mesh name="left_hip_roll_link" file="left_hip_roll_link.STL" />
    <mesh name="left_hip_yaw_link" file="left_hip_yaw_link.STL" />
    <mesh name="left_knee_link" file="left_knee_link.STL" />
    <mesh name="left_ankle_pitch_link" file="left_ankle_pitch_link.STL" />
    <mesh name="left_ankle_roll_link" file="left_ankle_roll_link.STL" />
    <mesh name="right_hip_pitch_link" file="right_hip_pitch_link.STL" />
    <mesh name="right_hip_roll_link" file="right_hip_roll_link.STL" />
    <mesh name="right_hip_yaw_link" file="right_hip_yaw_link.STL" />
    <mesh name="right_knee_link" file="right_knee_link.STL" />
    <mesh name="right_ankle_pitch_link" file="right_ankle_pitch_link.STL" />
    <mesh name="right_ankle_roll_link" file="right_ankle_roll_link.STL" />
    <mesh name="waist_yaw_link" file="waist_yaw_link.STL" />
    <mesh name="waist_roll_link" file="waist_roll_link.STL" />
    <mesh name="torso_link" file="torso_link.STL" />
    <mesh name="logo_link" file="logo_link.STL" />
    <mesh name="head_link" file="head_link.STL" />
    <mesh name="waist_support_link" file="waist_support_link.STL" />
    <mesh name="left_shoulder_pitch_link" file="left_shoulder_pitch_link.STL" />
    <mesh name="left_shoulder_roll_link" file="left_shoulder_roll_link.STL" />
    <mesh name="left_shoulder_yaw_link" file="left_shoulder_yaw_link.STL" />
    <mesh name="left_elbow_link" file="left_elbow_link.STL" />
    <mesh name="left_wrist_roll_link" file="left_wrist_roll_link.STL" />
    <mesh name="left_wrist_pitch_link" file="left_wrist_pitch_link.STL" />
    <mesh name="left_wrist_yaw_link" file="left_wrist_yaw_link.STL" />
    <mesh name="left_rubber_hand" file="left_rubber_hand.STL" />
    <mesh name="right_shoulder_pitch_link" file="right_shoulder_pitch_link.STL" />
    <mesh name="right_shoulder_roll_link" file="right_shoulder_roll_link.STL" />
    <mesh name="right_shoulder_yaw_link" file="right_shoulder_yaw_link.STL" />
    <mesh name="right_elbow_link" file="right_elbow_link.STL" />
    <mesh name="right_wrist_roll_link" file="right_wrist_roll_link.STL" />
    <mesh name="right_wrist_pitch_link" file="right_wrist_pitch_link.STL" />
    <mesh name="right_wrist_yaw_link" file="right_wrist_yaw_link.STL" />
    <mesh name="right_rubber_hand" file="right_rubber_hand.STL" />
    <texture type="skybox" builtin="gradient" rgb1="0.3 0.5 0.7" rgb2="0 0 0" width="512" height="3072" />
    <texture type="2d" name="groundplane" builtin="checker" mark="edge" rgb1="0.2 0.3 0.4" rgb2="0.1 0.2 0.3" markrgb="0.8 0.8 0.8" width="300" height="300" />
    <material name="groundplane" texture="groundplane" texuniform="true" texrepeat="5 5" reflectance="0.2" />
  </asset>
  <worldbody>
    <body name="pelvis" pos="0.0 0.0 0.793" quat="1.0 0.0 0.0 0.0">
      <inertial mass="3.813" pos="0.0 0.0 -0.07605" quat="0.9999999203404464 0.0 -0.000399147968204 0.0" diaginertia="0.010549 0.0093089 0.0079184" />
      <joint name="floating_base_joint" type="free" pos="0.0 0.0 0.0" axis="0.0 0.0 1.0" range="0.0 0.0" damping="0.0" stiffness="0.0"  frictionloss="0.0" />
      <geom type="mesh" mesh="pelvis" contype="0" conaffinity="0" pos="0.0 0.0 0.0" quat="1 0 0 0" rgba="0.2 0.2 0.2 1.0" />
      <geom type="mesh" mesh="pelvis_contour_link" contype="0" conaffinity="0" pos="0.0 0.0 0.0" quat="1 0 0 0" rgba="0.7 0.7 0.7 1.0" />
      <geom type="mesh" mesh="pelvis_contour_link" contype="1" conaffinity="1" pos="0.0 0.0 0.0" quat="1 0 0 0" rgba="0.7 0.7 0.7 1.0" />
      <body name="left_hip_pitch_link" pos="0.0 0.064452 -0.1027" quat="1.0 0.0 0.0 0.0">
        <inertial mass="1.35" pos="0.002741 0.047791 -0.02606" quat="0.954862473346758 0.2939641457246244 0.0302556149983873 0.0301220149321588" diaginertia="0.00181517 0.00153422 0.00116212" />
        <joint name="left_hip_pitch_joint" type="hinge" pos="0.0 0.0 0.0" axis="0.0 1.0 0.0" range="-2.5307 2.8798" damping="0.0" stiffness="0.0"  frictionloss="0.0" />
        <geom type="mesh" mesh="left_hip_pitch_link" contype="0" conaffinity="0" pos="0.0 0.0 0.0" quat="1 0 0 0" rgba="0.2 0.2 0.2 1.0" />
        <geom type="mesh" mesh="left_hip_pitch_link" contype="1" conaffinity="1" pos="0.0 0.0 0.0" quat="1 0 0 0" rgba="0.2 0.2 0.2 1.0" />
        <body name="left_hip_roll_link" pos="0.0 0.052 -0.030465" quat="0.996178685660368 0.0 -0.0873385724407125 0.0">
          <inertial mass="1.52" pos="0.029812 -0.001045 -0.087934" quat="0.9778077727100524 -1.9711895417999528e-05 0.2055759522141788 -0.0403792906138945" diaginertia="0.00254986 0.00241169 0.00148755" />
          <joint name="left_hip_roll_joint" type="hinge" pos="0.0 0.0 0.0" axis="1.0 0.0 0.0" range="-0.5236 2.9671" damping="0.0" stiffness="0.0"  frictionloss="0.0" />
          <geom type="mesh" mesh="left_hip_roll_link" contype="0" conaffinity="0" pos="0.0 0.0 0.0" quat="1 0 0 0" rgba="0.7 0.7 0.7 1.0" />
          <geom type="mesh" mesh="left_hip_roll_link" contype="1" conaffinity="1" pos="0.0 0.0 0.0" quat="1 0 0 0" rgba="0.7 0.7 0.7 1.0" />
          <body name="left_hip_yaw_link" pos="0.025001 0.0 -0.12412" quat="1.0 0.0 0.0 0.0">
            <inertial mass="1.702" pos="-0.057709 -0.010981 -0.15078" quat="0.6005979161898699 0.1583199779073194 0.2234819688143225 0.7511808951768449" diaginertia="0.00776166 0.00717575 0.00160139" />
            <joint name="left_hip_yaw_joint" type="hinge" pos="0.0 0.0 0.0" axis="0.0 0.0 1.0" range="-2.7576 2.7576" damping="0.0" stiffness="0.0"  frictionloss="0.0" />
            <geom type="mesh" mesh="left_hip_yaw_link" contype="0" conaffinity="0" pos="0.0 0.0 0.0" quat="1 0 0 0" rgba="0.7 0.7 0.7 1.0" />
            <geom type="mesh" mesh="left_hip_yaw_link" contype="1" conaffinity="1" pos="0.0 0.0 0.0" quat="1 0 0 0" rgba="0.7 0.7 0.7 1.0" />
            <body name="left_knee_link" pos="-0.078273 0.0021489 -0.17734" quat="0.996178685660368 0.0 0.0873385724407125 0.0">
              <inertial mass="1.932" pos="0.005457 0.003964 -0.12074" quat="0.923417870941202 -0.0327698954200114 0.0158245977883213 0.3820669466015307" diaginertia="0.0113804 0.0112778 0.00146458" />
              <joint name="left_knee_joint" type="hinge" pos="0.0 0.0 0.0" axis="0.0 1.0 0.0" range="-0.087267 2.8798" damping="0.0" stiffness="0.0"  frictionloss="0.0" />
              <geom type="mesh" mesh="left_knee_link" contype="0" conaffinity="0" pos="0.0 0.0 0.0" quat="1 0 0 0" rgba="0.7 0.7 0.7 1.0" />
              <geom type="mesh" mesh="left_knee_link" contype="1" conaffinity="1" pos="0.0 0.0 0.0" quat="1 0 0 0" rgba="0.7 0.7 0.7 1.0" />
              <body name="left_ankle_pitch_link" pos="0.0 -9.4445e-05 -0.30001" quat="1.0 0.0 0.0 0.0">
                <inertial mass="0.074" pos="-0.007269 0.0 0.011137" quat="0.6030529870741624 0.3692249920860316 0.3692249920860316 0.6030529870741624" diaginertia="1.89e-05 1.40805e-05 6.9195e-06" />
                <joint name="left_ankle_pitch_joint" type="hinge" pos="0.0 0.0 0.0" axis="0.0 1.0 0.0" range="-0.87267 0.5236" damping="0.0" stiffness="0.0"  frictionloss="0.0" />
                <geom type="mesh" mesh="left_ankle_pitch_link" contype="0" conaffinity="0" pos="0.0 0.0 0.0" quat="1 0 0 0" rgba="0.7 0.7 0.7 1.0" />
                <geom type="mesh" mesh="left_ankle_pitch_link" contype="1" conaffinity="1" pos="0.0 0.0 0.0" quat="1 0 0 0" rgba="0.7 0.7 0.7 1.0" />
                <body name="left_ankle_roll_link" pos="0.0 0.0 -0.017558" quat="1.0 0.0 0.0 0.0">
                  <inertial mass="0.608" pos="0.026505 0.0 -0.016425" quat="-0.0004810918332731 0.7284817475378975 -0.0006189667854913 0.6850647625844561" diaginertia="0.00167218 0.0016161 0.000217621" />
                  <joint name="left_ankle_roll_joint" type="hinge" pos="0.0 0.0 0.0" axis="1.0 0.0 0.0" range="-0.2618 0.2618" damping="0.0" stiffness="0.0"  frictionloss="0.0" />
                  <geom type="mesh" mesh="left_ankle_roll_link" contype="0" conaffinity="0" pos="0.0 0.0 0.0" quat="1 0 0 0" rgba="0.2 0.2 0.2 1.0" />
                  <geom rgba="0 0.7 0.3 0.1" type="sphere" pos="-0.05 0.025 -0.03" quat="1.0 0.0 0.0 0.0" size="0.005 0.0 0.0" contype="1" conaffinity="1" friction="1.0 0.005 0.0001" />
                  <geom rgba="0 0.7 0.3 0.1" type="sphere" pos="-0.05 -0.025 -0.03" quat="1.0 0.0 0.0 0.0" size="0.005 0.0 0.0" contype="1" conaffinity="1" friction="1.0 0.005 0.0001" />
                  <geom rgba="0 0.7 0.3 0.1" type="sphere" pos="0.12 0.03 -0.03" quat="1.0 0.0 0.0 0.0" size="0.005 0.0 0.0" contype="1" conaffinity="1" friction="1.0 0.005 0.0001" />
                  <geom rgba="0 0.7 0.3 0.1" type="sphere" pos="0.12 -0.03 -0.03" quat="1.0 0.0 0.0 0.0" size="0.005 0.0 0.0" contype="1" conaffinity="1" friction="1.0 0.005 0.0001" />
                </body>
              </body>
            </body>
          </body>
        </body>
      </body>
      <body name="right_hip_pitch_link" pos="0.0 -0.064452 -0.1027" quat="1.0 0.0 0.0 0.0">
        <inertial mass="1.35" pos="0.002741 -0.047791 -0.02606" quat="0.954862473346758 -0.2939641457246244 0.0302556149983873 -0.0301220149321588" diaginertia="0.00181517 0.00153422 0.00116212" />
        <joint name="right_hip_pitch_joint" type="hinge" pos="0.0 0.0 0.0" axis="0.0 1.0 0.0" range="-2.5307 2.8798" damping="0.0" stiffness="0.0"  frictionloss="0.0" />
        <geom type="mesh" mesh="right_hip_pitch_link" contype="0" conaffinity="0" pos="0.0 0.0 0.0" quat="1 0 0 0" rgba="0.2 0.2 0.2 1.0" />
        <geom type="mesh" mesh="right_hip_pitch_link" contype="1" conaffinity="1" pos="0.0 0.0 0.0" quat="1 0 0 0" rgba="0.2 0.2 0.2 1.0" />
        <body name="right_hip_roll_link" pos="0.0 -0.052 -0.030465" quat="0.996178685660368 0.0 -0.0873385724407125 0.0">
          <inertial mass="1.52" pos="0.029812 0.001045 -0.087934" quat="0.9778077727100524 1.9711895417999528e-05 0.2055759522141788 0.0403792906138945" diaginertia="0.00254986 0.00241169 0.00148755" />
          <joint name="right_hip_roll_joint" type="hinge" pos="0.0 0.0 0.0" axis="1.0 0.0 0.0" range="-2.9671 0.5236" damping="0.0" stiffness="0.0"  frictionloss="0.0" />
          <geom type="mesh" mesh="right_hip_roll_link" contype="0" conaffinity="0" pos="0.0 0.0 0.0" quat="1 0 0 0" rgba="0.7 0.7 0.7 1.0" />
          <geom type="mesh" mesh="right_hip_roll_link" contype="1" conaffinity="1" pos="0.0 0.0 0.0" quat="1 0 0 0" rgba="0.7 0.7 0.7 1.0" />
          <body name="right_hip_yaw_link" pos="0.025001 0.0 -0.12412" quat="1.0 0.0 0.0 0.0">
            <inertial mass="1.702" pos="-0.057709 0.010981 -0.15078" quat="0.7511808951768449 0.2234819688143225 0.1583199779073194 0.6005979161898699" diaginertia="0.00776166 0.00717575 0.00160139" />
            <joint name="right_hip_yaw_joint" type="hinge" pos="0.0 0.0 0.0" axis="0.0 0.0 1.0" range="-2.7576 2.7576" damping="0.0" stiffness="0.0"  frictionloss="0.0" />
            <geom type="mesh" mesh="right_hip_yaw_link" contype="0" conaffinity="0" pos="0.0 0.0 0.0" quat="1 0 0 0" rgba="0.7 0.7 0.7 1.0" />
            <geom type="mesh" mesh="right_hip_yaw_link" contype="1" conaffinity="1" pos="0.0 0.0 0.0" quat="1 0 0 0" rgba="0.7 0.7 0.7 1.0" />
            <body name="right_knee_link" pos="-0.078273 -0.0021489 -0.17734" quat="0.996178685660368 0.0 0.0873385724407125 0.0">
              <inertial mass="1.932" pos="0.005457 -0.003964 -0.12074" quat="0.9234388874809868 0.0345275957928878 0.0116332985825079 -0.3820119534526772" diaginertia="0.011374 0.0112843 0.00146452" />
              <joint name="right_knee_joint" type="hinge" pos="0.0 0.0 0.0" axis="0.0 1.0 0.0" range="-0.087267 2.8798" damping="0.0" stiffness="0.0"  frictionloss="0.0" />
              <geom type="mesh" mesh="right_knee_link" contype="0" conaffinity="0" pos="0.0 0.0 0.0" quat="1 0 0 0" rgba="0.7 0.7 0.7 1.0" />
              <geom type="mesh" mesh="right_knee_link" contype="1" conaffinity="1" pos="0.0 0.0 0.0" quat="1 0 0 0" rgba="0.7 0.7 0.7 1.0" />
              <body name="right_ankle_pitch_link" pos="0.0 9.4445e-05 -0.30001" quat="1.0 0.0 0.0 0.0">
                <inertial mass="0.074" pos="-0.007269 0.0 0.011137" quat="0.6030529870741624 0.3692249920860316 0.3692249920860316 0.6030529870741624" diaginertia="1.89e-05 1.40805e-05 6.9195e-06" />
                <joint name="right_ankle_pitch_joint" type="hinge" pos="0.0 0.0 0.0" axis="0.0 1.0 0.0" range="-0.87267 0.5236" damping="0.0" stiffness="0.0"  frictionloss="0.0" />
                <geom type="mesh" mesh="right_ankle_pitch_link" contype="0" conaffinity="0" pos="0.0 0.0 0.0" quat="1 0 0 0" rgba="0.7 0.7 0.7 1.0" />
                <geom type="mesh" mesh="right_ankle_pitch_link" contype="1" conaffinity="1" pos="0.0 0.0 0.0" quat="1 0 0 0" rgba="0.7 0.7 0.7 1.0" />
                <body name="right_ankle_roll_link" pos="0.0 0.0 -0.017558" quat="1.0 0.0 0.0 0.0">
                  <inertial mass="0.608" pos="0.026505 0.0 -0.016425" quat="0.0004810918332731 0.7284817475378975 0.0006189667854913 0.6850647625844561" diaginertia="0.00167218 0.0016161 0.000217621" />
                  <joint name="right_ankle_roll_joint" type="hinge" pos="0.0 0.0 0.0" axis="1.0 0.0 0.0" range="-0.2618 0.2618" damping="0.0" stiffness="0.0"  frictionloss="0.0" />
                  <geom type="mesh" mesh="right_ankle_roll_link" contype="0" conaffinity="0" pos="0.0 0.0 0.0" quat="1 0 0 0" rgba="0.2 0.2 0.2 1.0" />
                  <geom rgba="0 0.7 0.3 0.1" type="sphere" pos="-0.05 0.025 -0.03" quat="1.0 0.0 0.0 0.0" size="0.005 0.0 0.0" contype="1" conaffinity="1" friction="1.0 0.005 0.0001" />
                  <geom rgba="0 0.7 0.3 0.1" type="sphere" pos="-0.05 -0.025 -0.03" quat="1.0 0.0 0.0 0.0" size="0.005 0.0 0.0" contype="1" conaffinity="1" friction="1.0 0.005 0.0001" />
                  <geom rgba="0 0.7 0.3 0.1" type="sphere" pos="0.12 0.03 -0.03" quat="1.0 0.0 0.0 0.0" size="0.005 0.0 0.0" contype="1" conaffinity="1" friction="1.0 0.005 0.0001" />
                  <geom rgba="0 0.7 0.3 0.1" type="sphere" pos="0.12 -0.03 -0.03" quat="1.0 0.0 0.0 0.0" size="0.005 0.0 0.0" contype="1" conaffinity="1" friction="1.0 0.005 0.0001" />
                </body>
              </body>
            </body>
          </body>
        </body>
      </body>
      <body name="waist_yaw_link" pos="0.0 0.0 0.0" quat="1.0 0.0 0.0 0.0">
        <inertial mass="0.244" pos="0.003964 0.0 0.018769" quat="-0.0178291015742899 0.6284640554926809 0.0282471024941879 0.7771210686189307" diaginertia="0.000158561 0.000124229 9.67669e-05" />
        <joint name="waist_yaw_joint" type="hinge" pos="0.0 0.0 0.0" axis="0.0 0.0 1.0" range="-2.618 2.618" damping="0.0" stiffness="0.0"  frictionloss="0.0" />
        <geom type="mesh" mesh="waist_yaw_link" contype="0" conaffinity="0" pos="0.0 0.0 0.0" quat="1 0 0 0" rgba="0.7 0.7 0.7 1.0" />
        <body name="waist_roll_link" pos="-0.0039635 0.0 0.035" quat="1.0 0.0 0.0 0.0">
          <inertial mass="0.047" pos="0.0 -0.000236 0.010111" quat="0.9997900169144476 0.0204920003466836 0.0 0.0" diaginertia="7.515e-06 6.40206e-06 3.98394e-06" />
          <joint name="waist_roll_joint" type="hinge" pos="0.0 0.0 0.0" axis="1.0 0.0 0.0" range="-0.52 0.52" damping="0.0" stiffness="0.0"  frictionloss="0.0" />
          <geom type="mesh" mesh="waist_roll_link" contype="0" conaffinity="0" pos="0.0 0.0 0.0" quat="1 0 0 0" rgba="0.7 0.7 0.7 1.0" />
          <body name="torso_link" pos="0.0 0.0 0.019" quat="1.0 0.0 0.0 0.0">
            <inertial mass="9.598" pos="0.00331658 0.000261533 0.179856" quat="0.9998309708889912 0.0003762039890464 0.0179894994762189 -0.0037770398900279" diaginertia="0.12407 0.111951 0.0325382" />
            <joint name="waist_pitch_joint" type="hinge" pos="0.0 0.0 0.0" axis="0.0 1.0 0.0" range="-0.52 0.52" damping="0.0" stiffness="0.0"  frictionloss="0.0" />
            <geom type="mesh" mesh="torso_link" contype="0" conaffinity="0" pos="0.0 0.0 0.0" quat="1 0 0 0" rgba="0.7 0.7 0.7 1.0" />
            <geom type="mesh" mesh="torso_link" contype="1" conaffinity="1" pos="0.0 0.0 0.0" quat="1 0 0 0" rgba="0.7 0.7 0.7 1.0" />
            <geom type="mesh" mesh="logo_link" contype="0" conaffinity="0" pos="0.0039635 0.0 -0.054" quat="1 0 0 0" rgba="0.2 0.2 0.2 1.0" />
            <geom type="mesh" mesh="logo_link" contype="1" conaffinity="1" pos="0.0039635 0.0 -0.054" quat="1 0 0 0" rgba="0.2 0.2 0.2 1.0" />
            <geom type="mesh" mesh="head_link" contype="0" conaffinity="0" pos="0.0039635 0.0 -0.054" quat="1 0 0 0" rgba="0.2 0.2 0.2 1.0" />
            <geom type="mesh" mesh="head_link" contype="1" conaffinity="1" pos="0.0039635 0.0 -0.054" quat="1 0 0 0" rgba="0.2 0.2 0.2 1.0" />
            <geom type="mesh" mesh="waist_support_link" contype="0" conaffinity="0" pos="0.0039635 0.0 -0.054" quat="1 0 0 0" rgba="0.7 0.7 0.7 1.0" />
            <geom type="mesh" mesh="waist_support_link" contype="1" conaffinity="1" pos="0.0039635 0.0 -0.054" quat="1 0 0 0" rgba="0.7 0.7 0.7 1.0" />
            <body name="left_shoulder_pitch_link" pos="0.0039563 0.10022 0.23778" quat="0.9902641396131312 0.1392010196253599 1.387220195578278e-05 -9.868681391343435e-05">
              <inertial mass="0.718" pos="0.0 0.035892 -0.011628" quat="0.6541519182994919 0.0130457983706409 -0.3262669592507862 0.682249914790184" diaginertia="0.000465864 0.000432842 0.000406394" />
              <joint name="left_shoulder_pitch_joint" type="hinge" pos="0.0 0.0 0.0" axis="0.0 1.0 0.0" range="-3.0892 2.6704" damping="0.0" stiffness="0.0"  frictionloss="0.0" />
              <geom type="mesh" mesh="left_shoulder_pitch_link" contype="0" conaffinity="0" pos="0.0 0.0 0.0" quat="1 0 0 0" rgba="0.7 0.7 0.7 1.0" />
              <geom rgba="0 0.7 0.3 0.1" type="cylinder" pos="0.0 0.04 -0.01" quat="0.7071067811865475 0.0 0.7071067811865475 0.0" size="0.03 0.025 0.0" contype="1" conaffinity="1" friction="1.0 0.005 0.0001" />
              <body name="left_shoulder_roll_link" pos="0.0 0.038 -0.013831" quat="0.99026821914242 -0.1391720307982171 0.0 0.0">
                <inertial mass="0.643" pos="-0.000227 0.00727 -0.063243" quat="0.7012560252335278 -0.0196223007060757 -0.0071031702555957 0.7126040256418666" diaginertia="0.000691311 0.000618011 0.000388977" />
                <joint name="left_shoulder_roll_joint" type="hinge" pos="0.0 0.0 0.0" axis="1.0 0.0 0.0" range="-1.5882 2.2515" damping="0.0" stiffness="0.0"  frictionloss="0.0" />
                <geom type="mesh" mesh="left_shoulder_roll_link" contype="0" conaffinity="0" pos="0.0 0.0 0.0" quat="1 0 0 0" rgba="0.7 0.7 0.7 1.0" />
                <geom rgba="0 0.7 0.3 0.1" type="cylinder" pos="-0.004 0.006 -0.053" quat="1.0 0.0 0.0 0.0" size="0.03 0.015 0.0" contype="1" conaffinity="1" friction="1.0 0.005 0.0001" />
                <body name="left_shoulder_yaw_link" pos="0.0 0.00624 -0.1032" quat="1.0 0.0 0.0 0.0">
                  <inertial mass="0.734" pos="0.010773 -0.002949 -0.072009" quat="0.7168787147457542 -0.096482861608365 -0.0679941729443403 0.6871337265816254" diaginertia="0.00106187 0.00103217 0.000400661" />
                  <joint name="left_shoulder_yaw_joint" type="hinge" pos="0.0 0.0 0.0" axis="0.0 0.0 1.0" range="-2.618 2.618" damping="0.0" stiffness="0.0"  frictionloss="0.0" />
                  <geom type="mesh" mesh="left_shoulder_yaw_link" contype="0" conaffinity="0" pos="0.0 0.0 0.0" quat="1 0 0 0" rgba="0.7 0.7 0.7 1.0" />
                  <geom type="mesh" mesh="left_shoulder_yaw_link" contype="1" conaffinity="1" pos="0.0 0.0 0.0" quat="1 0 0 0" rgba="0.7 0.7 0.7 1.0" />
                  <body name="left_elbow_link" pos="0.015783 0.0 -0.080518" quat="1.0 0.0 0.0 0.0">
                    <inertial mass="0.6" pos="0.064956 0.004454 -0.010062" quat="0.5417652363909151 0.6361322775665198 0.3888211696561277 0.3881291693541839" diaginertia="0.000443035 0.000421612 0.000259353" />
                    <joint name="left_elbow_joint" type="hinge" pos="0.0 0.0 0.0" axis="0.0 1.0 0.0" range="-1.0472 2.0944" damping="0.0" stiffness="0.0"  frictionloss="0.0" />
                    <geom type="mesh" mesh="left_elbow_link" contype="0" conaffinity="0" pos="0.0 0.0 0.0" quat="1 0 0 0" rgba="0.7 0.7 0.7 1.0" />
                    <geom type="mesh" mesh="left_elbow_link" contype="1" conaffinity="1" pos="0.0 0.0 0.0" quat="1 0 0 0" rgba="0.7 0.7 0.7 1.0" />
                    <body name="left_wrist_roll_link" pos="0.1 0.00188791 -0.01" quat="1.0 0.0 0.0 0.0">
                      <inertial mass="0.085445" pos="0.0171394 0.000537591 4.8864e-07" quat="0.5753383685604386 0.4116672637131044 -0.5749063682837002 0.4110942633460417" diaginertia="5.48211e-05 4.96646e-05 3.57798e-05" />
                      <joint name="left_wrist_roll_joint" type="hinge" pos="0.0 0.0 0.0" axis="1.0 0.0 0.0" range="-1.97222 1.97222" damping="0.0" stiffness="0.0"  frictionloss="0.0" />
                      <geom type="mesh" mesh="left_wrist_roll_link" contype="0" conaffinity="0" pos="0.0 0.0 0.0" quat="1 0 0 0" rgba="0.7 0.7 0.7 1.0" />
                      <geom type="mesh" mesh="left_wrist_roll_link" contype="1" conaffinity="1" pos="0.0 0.0 0.0" quat="1 0 0 0" rgba="0.7 0.7 0.7 1.0" />
                      <body name="left_wrist_pitch_link" pos="0.038 0.0 0.0" quat="1.0 0.0 0.0 0.0">
                        <inertial mass="0.48405" pos="0.0229999 -0.00111685 -0.00111658" quat="0.2499978284099243 0.6613625460630598 0.2930357988701134 0.6436075582494845" diaginertia="0.000430353 0.000429873 0.000164648" />
                        <joint name="left_wrist_pitch_joint" type="hinge" pos="0.0 0.0 0.0" axis="0.0 1.0 0.0" range="-1.61443 1.61443" damping="0.0" stiffness="0.0"  frictionloss="0.0" />
                        <geom type="mesh" mesh="left_wrist_pitch_link" contype="0" conaffinity="0" pos="0.0 0.0 0.0" quat="1 0 0 0" rgba="0.7 0.7 0.7 1.0" />
                        <geom type="mesh" mesh="left_wrist_pitch_link" contype="1" conaffinity="1" pos="0.0 0.0 0.0" quat="1 0 0 0" rgba="0.7 0.7 0.7 1.0" />
                        <body name="left_wrist_yaw_link" pos="0.046 0.0 0.0" quat="1.0 0.0 0.0 0.0">
                          <inertial mass="0.254576" pos="0.0708244 0.000191745 0.00161742" quat="0.5105708492555107 0.5262948446130489 0.4680778618014359 0.493187854387787" diaginertia="0.000646113 0.000559993 0.000147566" />
                          <joint name="left_wrist_yaw_joint" type="hinge" pos="0.0 0.0 0.0" axis="0.0 0.0 1.0" range="-1.61443 1.61443" damping="0.0" stiffness="0.0"  frictionloss="0.0" />
                          <geom type="mesh" mesh="left_wrist_yaw_link" contype="0" conaffinity="0" pos="0.0 0.0 0.0" quat="1 0 0 0" rgba="0.7 0.7 0.7 1.0" />
                          <geom type="mesh" mesh="left_wrist_yaw_link" contype="1" conaffinity="1" pos="0.0 0.0 0.0" quat="1 0 0 0" rgba="0.7 0.7 0.7 1.0" />
                          <geom type="mesh" mesh="left_rubber_hand" contype="1" conaffinity="1" pos="0.0415 0.003 0.0" quat="1 0 0 0" rgba="0.7 0.7 0.7 1.0" />
                        </body>
                      </body>
                    </body>
                  </body>
                </body>
              </body>
            </body>
            <body name="right_shoulder_pitch_link" pos="0.0039563 -0.10021 0.23778" quat="0.9902641396131312 -0.1392010196253599 1.387220195578278e-05 9.868681391343435e-05">
              <inertial mass="0.718" pos="0.0 -0.035892 -0.011628" quat="0.682249914790184 -0.3262669592507862 0.0130457983706409 0.6541519182994919" diaginertia="0.000465864 0.000432842 0.000406394" />
              <joint name="right_shoulder_pitch_joint" type="hinge" pos="0.0 0.0 0.0" axis="0.0 1.0 0.0" range="-3.0892 2.6704" damping="0.0" stiffness="0.0"  frictionloss="0.0" />
              <geom type="mesh" mesh="right_shoulder_pitch_link" contype="0" conaffinity="0" pos="0.0 0.0 0.0" quat="1 0 0 0" rgba="0.7 0.7 0.7 1.0" />
              <geom rgba="0 0.7 0.3 0.1" type="cylinder" pos="0.0 -0.04 -0.01" quat="0.7071067811865475 0.0 0.7071067811865475 0.0" size="0.03 0.025 0.0" contype="1" conaffinity="1" friction="1.0 0.005 0.0001" />
              <body name="right_shoulder_roll_link" pos="0.0 -0.038 -0.013831" quat="0.99026821914242 0.1391720307982171 0.0 0.0">
                <inertial mass="0.643" pos="-0.000227 -0.00727 -0.063243" quat="0.7126040256418666 -0.0071031702555957 -0.0196223007060757 0.7012560252335278" diaginertia="0.000691311 0.000618011 0.000388977" />
                <joint name="right_shoulder_roll_joint" type="hinge" pos="0.0 0.0 0.0" axis="1.0 0.0 0.0" range="-2.2515 1.5882" damping="0.0" stiffness="0.0"  frictionloss="0.0" />
                <geom type="mesh" mesh="right_shoulder_roll_link" contype="0" conaffinity="0" pos="0.0 0.0 0.0" quat="1 0 0 0" rgba="0.7 0.7 0.7 1.0" />
                <geom rgba="0 0.7 0.3 0.1" type="cylinder" pos="-0.004 -0.006 -0.053" quat="1.0 0.0 0.0 0.0" size="0.03 0.015 0.0" contype="1" conaffinity="1" friction="1.0 0.005 0.0001" />
                <body name="right_shoulder_yaw_link" pos="0.0 -0.00624 -0.1032" quat="1.0 0.0 0.0 0.0">
                  <inertial mass="0.734" pos="0.010773 0.002949 -0.072009" quat="0.6871337265816254 -0.0679941729443403 -0.096482861608365 0.7168787147457542" diaginertia="0.00106187 0.00103217 0.000400661" />
                  <joint name="right_shoulder_yaw_joint" type="hinge" pos="0.0 0.0 0.0" axis="0.0 0.0 1.0" range="-2.618 2.618" damping="0.0" stiffness="0.0"  frictionloss="0.0" />
                  <geom type="mesh" mesh="right_shoulder_yaw_link" contype="0" conaffinity="0" pos="0.0 0.0 0.0" quat="1 0 0 0" rgba="0.7 0.7 0.7 1.0" />
                  <geom type="mesh" mesh="right_shoulder_yaw_link" contype="1" conaffinity="1" pos="0.0 0.0 0.0" quat="1 0 0 0" rgba="0.7 0.7 0.7 1.0" />
                  <body name="right_elbow_link" pos="0.015783 0.0 -0.080518" quat="1.0 0.0 0.0 0.0">
                    <inertial mass="0.6" pos="0.064956 -0.004454 -0.010062" quat="0.3881291693541839 0.3888211696561276 0.6361322775665197 0.5417652363909151" diaginertia="0.000443035 0.000421612 0.000259353" />
                    <joint name="right_elbow_joint" type="hinge" pos="0.0 0.0 0.0" axis="0.0 1.0 0.0" range="-1.0472 2.0944" damping="0.0" stiffness="0.0"  frictionloss="0.0" />
                    <geom type="mesh" mesh="right_elbow_link" contype="0" conaffinity="0" pos="0.0 0.0 0.0" quat="1 0 0 0" rgba="0.7 0.7 0.7 1.0" />
                    <geom type="mesh" mesh="right_elbow_link" contype="1" conaffinity="1" pos="0.0 0.0 0.0" quat="1 0 0 0" rgba="0.7 0.7 0.7 1.0" />
                    <body name="right_wrist_roll_link" pos="0.1 -0.00188791 -0.01" quat="1.0 0.0 0.0 0.0">
                      <inertial mass="0.085445" pos="0.0171394 -0.000537591 4.8864e-07" quat="0.4116672637131044 0.5753383685604386 -0.4110942633460417 0.5749063682837002" diaginertia="5.48211e-05 4.96646e-05 3.57798e-05" />
                      <joint name="right_wrist_roll_joint" type="hinge" pos="0.0 0.0 0.0" axis="1.0 0.0 0.0" range="-1.97222 1.97222" damping="0.0" stiffness="0.0"  frictionloss="0.0" />
                      <geom type="mesh" mesh="right_wrist_roll_link" contype="0" conaffinity="0" pos="0.0 0.0 0.0" quat="1 0 0 0" rgba="0.7 0.7 0.7 1.0" />
                      <geom type="mesh" mesh="right_wrist_roll_link" contype="1" conaffinity="1" pos="0.0 0.0 0.0" quat="1 0 0 0" rgba="0.7 0.7 0.7 1.0" />
                      <body name="right_wrist_pitch_link" pos="0.038 0.0 0.0" quat="1.0 0.0 0.0 0.0">
                        <inertial mass="0.48405" pos="0.0229999 0.00111685 -0.00111658" quat="0.6436075582494845 0.2930357988701134 0.6613625460630598 0.2499978284099243" diaginertia="0.000430353 0.000429873 0.000164648" />
                        <joint name="right_wrist_pitch_joint" type="hinge" pos="0.0 0.0 0.0" axis="0.0 1.0 0.0" range="-1.61443 1.61443" damping="0.0" stiffness="0.0"  frictionloss="0.0" />
                        <geom type="mesh" mesh="right_wrist_pitch_link" contype="0" conaffinity="0" pos="0.0 0.0 0.0" quat="1 0 0 0" rgba="0.7 0.7 0.7 1.0" />
                        <geom type="mesh" mesh="right_wrist_pitch_link" contype="1" conaffinity="1" pos="0.0 0.0 0.0" quat="1 0 0 0" rgba="0.7 0.7 0.7 1.0" />
                        <body name="right_wrist_yaw_link" pos="0.046 0.0 0.0" quat="1.0 0.0 0.0 0.0">
                          <inertial mass="0.254576" pos="0.0708244 -0.000191745 0.00161742" quat="0.493187854387787 0.4680778618014359 0.5262948446130489 0.5105708492555107" diaginertia="0.000646113 0.000559993 0.000147566" />
                          <joint name="right_wrist_yaw_joint" type="hinge" pos="0.0 0.0 0.0" axis="0.0 0.0 1.0" range="-1.61443 1.61443" damping="0.0" stiffness="0.0"  frictionloss="0.0" />
                          <geom type="mesh" mesh="right_wrist_yaw_link" contype="0" conaffinity="0" pos="0.0 0.0 0.0" quat="1 0 0 0" rgba="0.7 0.7 0.7 1.0" />
                          <geom type="mesh" mesh="right_wrist_yaw_link" contype="1" conaffinity="1" pos="0.0 0.0 0.0" quat="1 0 0 0" rgba="0.7 0.7 0.7 1.0" />
                          <geom type="mesh" mesh="right_rubber_hand" contype="1" conaffinity="1" pos="0.0415 -0.003 0.0" quat="1 0 0 0" rgba="0.7 0.7 0.7 1.0" />
                        </body>
                      </body>
                    </body>
                  </body>
                </body>
              </body>
            </body>
          </body>
        </body>
      </body>
    </body>
    <light pos="0 0 3.5" dir="0 0 -1" directional="true" />
    <geom name="floor" size="0 0 0.05" type="plane" material="groundplane" condim="3" conaffinity="1" contype="1" friction="1.0 0.005 0.0001" />
  </worldbody>
  <actuator>
    <motor name="left_hip_pitch_joint" joint="left_hip_pitch_joint" ctrlrange="-100 100" />
    <motor name="left_hip_roll_joint" joint="left_hip_roll_joint" ctrlrange="-100 100" />
    <motor name="left_hip_yaw_joint" joint="left_hip_yaw_joint" ctrlrange="-100 100" />
    <motor name="left_knee_joint" joint="left_knee_joint" ctrlrange="-139 139" />
    <motor name="left_ankle_pitch_joint" joint="left_ankle_pitch_joint" ctrlrange="-100 100" />
    <motor name="left_ankle_roll_joint" joint="left_ankle_roll_joint" ctrlrange="-100 100" />
    <motor name="right_hip_pitch_joint" joint="right_hip_pitch_joint" ctrlrange="-100 100" />
    <motor name="right_hip_roll_joint" joint="right_hip_roll_joint" ctrlrange="-100 100" />
    <motor name="right_hip_yaw_joint" joint="right_hip_yaw_joint" ctrlrange="-100 100" />
    <motor name="right_knee_joint" joint="right_knee_joint" ctrlrange="-139 139" />
    <motor name="right_ankle_pitch_joint" joint="right_ankle_pitch_joint" ctrlrange="-100 100" />
    <motor name="right_ankle_roll_joint" joint="right_ankle_roll_joint" ctrlrange="-100 100" />
    <motor name="waist_yaw_joint" joint="waist_yaw_joint" ctrlrange="-100 100" />
    <motor name="waist_roll_joint" joint="waist_roll_joint" ctrlrange="-100 100" />
    <motor name="waist_pitch_joint" joint="waist_pitch_joint" ctrlrange="-100 100" />
    <motor name="left_shoulder_pitch_joint" joint="left_shoulder_pitch_joint" ctrlrange="-100 100" />
    <motor name="left_shoulder_roll_joint" joint="left_shoulder_roll_joint" ctrlrange="-100 100" />
    <motor name="left_shoulder_yaw_joint" joint="left_shoulder_yaw_joint" ctrlrange="-100 100" />
    <motor name="left_elbow_joint" joint="left_elbow_joint" ctrlrange="-100 100" />
    <motor name="left_wrist_roll_joint" joint="left_wrist_roll_joint" ctrlrange="-100 100" />
    <motor name="left_wrist_pitch_joint" joint="left_wrist_pitch_joint" ctrlrange="-100 100" />
    <motor name="left_wrist_yaw_joint" joint="left_wrist_yaw_joint" ctrlrange="-100 100" />
    <motor name="right_shoulder_pitch_joint" joint="right_shoulder_pitch_joint" ctrlrange="-100 100" />
    <motor name="right_shoulder_roll_joint" joint="right_shoulder_roll_joint" ctrlrange="-100 100" />
    <motor name="right_shoulder_yaw_joint" joint="right_shoulder_yaw_joint" ctrlrange="-100 100" />
    <motor name="right_elbow_joint" joint="right_elbow_joint" ctrlrange="-100 100" />
    <motor name="right_wrist_roll_joint" joint="right_wrist_roll_joint" ctrlrange="-100 100" />
    <motor name="right_wrist_pitch_joint" joint="right_wrist_pitch_joint" ctrlrange="-100 100" />
    <motor name="right_wrist_yaw_joint" joint="right_wrist_yaw_joint" ctrlrange="-100 100" />
  </actuator>
  <visual>
    <headlight diffuse="0.6 0.6 0.6" ambient="0.3 0.3 0.3" specular="0 0 0" />
    <rgba haze="0.15 0.25 0.35 1" />
    <global azimuth="160" elevation="-20" />
  </visual>
</mujoco>